2019-05-22 11:14:05,253 - requests - ERROR - base  - 72 - 读取配置报错
Traceback (most recent call last):
  File "C:\Users\DG02\AppData\Local\Programs\Python\Python37\lib\configparser.py", line 788, in get
    value = d[option]
  File "C:\Users\DG02\AppData\Local\Programs\Python\Python37\lib\collections\__init__.py", line 914, in __getitem__
    return self.__missing__(key)            # support subclasses that define __missing__
  File "C:\Users\DG02\AppData\Local\Programs\Python\Python37\lib\collections\__init__.py", line 906, in __missing__
    raise KeyError(key)
KeyError: 'username'

During handling of the above exception, another exception occurred:

Traceback (most recent call last):
  File "C:\Users\DG02\PycharmProjects\RequestsTestDemo\Common\base.py", line 69, in config_read
    config_get = config.get(section, key)
  File "C:\Users\DG02\AppData\Local\Programs\Python\Python37\lib\configparser.py", line 791, in get
    raise NoOptionError(option, section)
configparser.NoOptionError: No option 'username' in section: 'sender'
2019-05-22 11:14:05,256 - requests - ERROR - sendMail  - 59 - 邮件发送失败
Traceback (most recent call last):
  File "C:/Users/DG02/PycharmProjects/RequestsTestDemo/Common/sendMail.py", line 30, in send_mail
    message['From'] = formataddr([usernmae, email])  # 括号里的对应发件人邮箱昵称、发件人邮箱账号
  File "C:\Users\DG02\AppData\Local\Programs\Python\Python37\lib\email\utils.py", line 91, in formataddr
    address.encode('ascii')
UnicodeEncodeError: 'ascii' codec can't encode characters in position 0-4: ordinal not in range(128)
